#VRML_SIM R2022a utf8
WorldInfo {
  basicTimeStep 16
  physicsDisableTime 0
}
Viewpoint {
  orientation 0.1782668465189886 -0.24949143024326947 -0.9518271679603095 5.1187777692276875
  position -1.7267835217814294 -3.9207228588882117 1.6503272011652435
}
TexturedBackground {
}
TexturedBackgroundLight {
}
RectangleArena {
  floorSize 2 2
  floorTileSize 0.25 0.25
  wallHeight 0.15
}
Robot {
  name "supervisor"
  controller "supervisor_controller"
  supervisor TRUE
}
DEF DWROBOT Robot {
  translation 0 0 0.05
  children [
    Lidar {
      translation 0 0 0.04
      horizontalResolution 4
      fieldOfView 6.2832
      numberOfLayers 1
    }
    HingeJoint {
      jointParameters HingeJointParameters {
        anchor 0.055 0 -0.021
      }
      device [
        RotationalMotor {
          name "left motor"
        }
      ]
      endPoint Solid {
        translation 0.055 0 -0.021
        rotation -5.151090574169847e-10 1 -3.493298326754779e-09 1.5706999999971307
        children [
          DEF WHEEL Shape {
            appearance PBRAppearance {
              roughness 1
              metalness 0
            }
            geometry Cylinder {
              height 0.01
              radius 0.03
            }
          }
        ]
        name "solid(2)"
        boundingObject USE WHEEL
        physics Physics {
        }
      }
    }
    HingeJoint {
      jointParameters HingeJointParameters {
        anchor -0.055 0 -0.021
      }
      device [
        RotationalMotor {
          name "right motor"
        }
      ]
      endPoint Solid {
        translation -0.0560179 0.00010214017687657157 -0.020916325525328083
        rotation 0.0001419268911189058 0.999999977383633 -0.00015839662555895166 4.712501676010415
        children [
          USE WHEEL
        ]
        name "solid(1)"
        boundingObject USE WHEEL
        physics Physics {
        }
      }
    }
    Solid {
      children [
        Shape {
          appearance PBRAppearance {
            baseColor 1 0 0
            roughness 1
            metalness 0
          }
          geometry Cylinder {
            height 0.1
            radius 0.05
          }
        }
      ]
    }
  ]
  boundingObject Cylinder {
    height 0.1
    radius 0.065
  }
  physics Physics {
  }
  controller "dwrobot_controller"
  customData "1.267655038552221 0.5058630849124508;-0.002267655038552221;"
}
