#VRML_SIM R2022a utf8
WorldInfo {
  basicTimeStep 8
  physicsDisableTime 0
}
Viewpoint {
  orientation 0.5930318947296911 -0.5730558313095256 -0.5656148743053537 4.176293613320578
  position -0.7536344611133325 0.16987169033229932 7.152573942022798
}
TexturedBackground {
}
TexturedBackgroundLight {
}
RectangleArena {
  floorSize 2 2
  floorTileSize 0.25 0.25
  wallHeight 0.15
}
Robot {
  name "supervisor"
  controller "supervisor_controller"
  supervisor TRUE
}
DEF DWROBOT Robot {
  translation 0 0 0.08
  children [
    Display {
      width 640
      height 360
    }
    Lidar {
      translation 0 0 0.04
      horizontalResolution 4
      fieldOfView 6.2832
      numberOfLayers 1
    }
    HingeJoint {
      jointParameters HingeJointParameters {
        anchor 0.057 0 -0.04
      }
      device [
        RotationalMotor {
          name "left motor"
        }
      ]
      endPoint Solid {
        translation 0.057 0 -0.04
        rotation -0.0902344140737853 0.9914632205129418 -0.09411924822726937 1.5765596662945982
        children [
          DEF WHEEL Shape {
            appearance PBRAppearance {
              roughness 1
              metalness 0
            }
            geometry Cylinder {
              height 0.01
              radius 0.03
            }
          }
        ]
        name "solid(2)"
        boundingObject USE WHEEL
        physics Physics {
        }
      }
    }
    HingeJoint {
      jointParameters HingeJointParameters {
        anchor -0.057 0 -0.04
      }
      device [
        RotationalMotor {
          name "right motor"
        }
      ]
      endPoint Solid {
        translation -0.057 0 -0.04
        rotation -0.38942672908652864 -0.8346281358279033 0.38954165060671814 1.7483068330744849
        children [
          USE WHEEL
        ]
        name "solid(1)"
        boundingObject USE WHEEL
        physics Physics {
        }
      }
    }
    BallJoint {
      jointParameters BallJointParameters {
        anchor 0 0.03 -0.06
      }
      jointParameters2 JointParameters {
      }
      jointParameters3 JointParameters {
        axis 0 1 0
      }
      endPoint Solid {
        translation 0 0.03 -0.06
        rotation 0.9999876185692977 -0.004827755263069842 0.0012064357523863224 0.6585170557449751
        children [
          Shape {
            appearance PBRAppearance {
              roughness 1
              metalness 0
            }
            geometry DEF BALL_WHEEL Sphere {
              radius 0.01
              subdivision 3
            }
          }
        ]
        name "solid(3)"
        boundingObject USE BALL_WHEEL
        physics Physics {
        }
      }
    }
    BallJoint {
      jointParameters BallJointParameters {
        anchor 0 -0.03 -0.06
      }
      jointParameters2 JointParameters {
      }
      jointParameters3 JointParameters {
        axis 0 1 0
      }
      endPoint Solid {
        translation 0 -0.03 -0.06
        rotation 0.9999876185692977 -0.004827755263070758 0.001206435752381353 0.6585170557449695
        children [
          Shape {
            appearance PBRAppearance {
              roughness 1
              metalness 0
            }
            geometry DEF BALL_WHEEL Sphere {
              radius 0.01
              subdivision 3
            }
          }
        ]
        name "solid(4)"
        boundingObject USE BALL_WHEEL
        physics Physics {
        }
      }
    }
    Solid {
      rotation 0 0 1 3.1415
      children [
        Shape {
          appearance PBRAppearance {
            baseColor 1 0 0
            roughness 1
            metalness 0
          }
          geometry Cylinder {
            height 0.1
            radius 0.05
          }
        }
      ]
      boundingObject Shape {
        geometry Cylinder {
          height 0.1
          radius 0.05
        }
      }
      physics Physics {
      }
    }
  ]
  boundingObject Cylinder {
    height 0.1
    radius 0.07
  }
  physics Physics {
  }
  controller "dwrobot_controller"
  customData "1.3852063315090182 0.33274596485888963;-3.316284227359745e-05;"
}
