#VRML_SIM R2022a utf8
WorldInfo {
  basicTimeStep 8
  physicsDisableTime 0
}
Viewpoint {
  orientation 0.5140740702023664 -0.44949284089041686 -0.7305368138114839 4.318166057453726
  position -0.18364621013751878 -3.086915176004201 7.958013558779007
}
TexturedBackground {
}
TexturedBackgroundLight {
}
RectangleArena {
  floorSize 2 2
  floorTileSize 0.25 0.25
  wallHeight 0.15
}
Robot {
  name "supervisor"
  controller "supervisor_controller"
  supervisor TRUE
}
DEF DWROBOT Robot {
  translation 0 0 0.08
  children [
    Display {
      width 640
      height 360
    }
    Lidar {
      translation 0 0 0.04
      horizontalResolution 4
      fieldOfView 6.2832
      numberOfLayers 1
    }
    HingeJoint {
      jointParameters HingeJointParameters {
        anchor 0.057 0 -0.04
      }
      device [
        RotationalMotor {
          name "left motor"
        }
      ]
      endPoint Solid {
        translation 0.057 0 -0.04
        rotation -0.09023441407378537 0.9914632205129418 -0.09411924822726934 1.5765596662945986
        children [
          DEF WHEEL Shape {
            appearance PBRAppearance {
              roughness 1
              metalness 0
            }
            geometry Cylinder {
              height 0.01
              radius 0.03
            }
          }
        ]
        name "solid(2)"
        boundingObject USE WHEEL
        physics Physics {
        }
      }
    }
    HingeJoint {
      jointParameters HingeJointParameters {
        anchor -0.057 0 -0.04
      }
      device [
        RotationalMotor {
          name "right motor"
        }
      ]
      endPoint Solid {
        translation -0.057 0 -0.04
        rotation -0.3894267290865289 -0.8346281358279032 0.389541650606718 1.7483068330744849
        children [
          USE WHEEL
        ]
        name "solid(1)"
        boundingObject USE WHEEL
        physics Physics {
        }
      }
    }
    BallJoint {
      jointParameters BallJointParameters {
        anchor 0 0.03 -0.06
      }
      jointParameters2 JointParameters {
      }
      jointParameters3 JointParameters {
        axis 0 1 0
      }
      endPoint Solid {
        translation 0 0.03 -0.06
        rotation 0.9999876185692979 -0.0048277552630728955 0.0012064357523842288 0.658517055744995
        children [
          Shape {
            appearance PBRAppearance {
              roughness 1
              metalness 0
            }
            geometry DEF BALL_WHEEL Sphere {
              radius 0.01
              subdivision 3
            }
          }
        ]
        name "solid(3)"
        boundingObject USE BALL_WHEEL
        physics Physics {
        }
      }
    }
    BallJoint {
      jointParameters BallJointParameters {
        anchor 0 -0.03 -0.06
      }
      jointParameters2 JointParameters {
      }
      jointParameters3 JointParameters {
        axis 0 1 0
      }
      endPoint Solid {
        translation 0 -0.03 -0.06
        rotation 0.9999876185692979 -0.0048277552630728955 0.0012064357523842288 0.658517055744995
        children [
          Shape {
            appearance PBRAppearance {
              roughness 1
              metalness 0
            }
            geometry DEF BALL_WHEEL Sphere {
              radius 0.01
              subdivision 3
            }
          }
        ]
        name "solid(4)"
        boundingObject USE BALL_WHEEL
        physics Physics {
        }
      }
    }
    Solid {
      children [
        Shape {
          appearance PBRAppearance {
            baseColor 1 0 0
            roughness 1
            metalness 0
          }
          geometry Cylinder {
            height 0.1
            radius 0.05
          }
        }
      ]
      boundingObject Shape {
        geometry Cylinder {
          height 0.1
          radius 0.05
        }
      }
      physics Physics {
      }
    }
  ]
  boundingObject Cylinder {
    height 0.1
    radius 0.07
  }
  physics Physics {
  }
  controller "dwrobot_controller"
  customData "0.5551197690764273 1.1029815045539477;-0.0005551197690764274;"
}
