#VRML_SIM R2022a utf8
WorldInfo {
  basicTimeStep 16
  physicsDisableTime 0
}
Viewpoint {
  orientation 0.5871089822486579 -0.5786685226103928 -0.5660793088453686 4.194089157474577
  position 0.11480665791658193 0.055339695686408286 4.205144550033143
}
TexturedBackground {
}
TexturedBackgroundLight {
}
RectangleArena {
  floorTileSize 0.25 0.25
  wallHeight 0.15
}
Robot {
  name "supervisor"
  controller "supervisor_controller"
  supervisor TRUE
}
DEF DWROBOT Robot {
  translation 0 0 0.05
  children [
    Lidar {
      translation 0 0 0.04
      horizontalResolution 8
      fieldOfView 6.2832
      numberOfLayers 1
    }
    HingeJoint {
      jointParameters HingeJointParameters {
        anchor 0.055 0 -0.021
      }
      device [
        RotationalMotor {
          name "left motor"
        }
      ]
      endPoint Solid {
        translation 0.055 0 -0.021
        rotation -5.151090279763327e-10 1 -3.493298316941226e-09 1.5706999999971316
        children [
          DEF WHEEL Shape {
            appearance PBRAppearance {
              roughness 1
              metalness 0
            }
            geometry Cylinder {
              height 0.01
              radius 0.03
            }
          }
        ]
        name "solid(2)"
        boundingObject USE WHEEL
        physics Physics {
        }
      }
    }
    HingeJoint {
      jointParameters HingeJointParameters {
        anchor -0.055 0 -0.021
      }
      device [
        RotationalMotor {
          name "right motor"
        }
      ]
      endPoint Solid {
        translation -0.0560179 0.00010214017687657209 -0.020916325525328083
        rotation 0.00014192689111937679 0.999999977383633 -0.00015839662555879454 4.712501676010415
        children [
          USE WHEEL
        ]
        name "solid(1)"
        boundingObject USE WHEEL
        physics Physics {
        }
      }
    }
    Solid {
      children [
        Shape {
          appearance PBRAppearance {
            baseColor 1 0 0
            roughness 1
            metalness 0
          }
          geometry Cylinder {
            height 0.1
            radius 0.05
          }
        }
      ]
    }
  ]
  boundingObject Cylinder {
    height 0.1
    radius 0.065
  }
  physics Physics {
  }
  controller "dwrobot_controller"
  customData "-0.002255599828152354 0.0476881589091112 -0.01315127098763067 0.4249170575637651 0.7281024044376752;0.000701795234109793;"
}
